<sdf version='1.7'>
  <model name='m2wr'>
    <link name='link_chassis'>
      <inertial>
        <pose>0.025 0 0.091667 0 -0 0</pose>
        <mass>10</mass>
        <inertia>
          <ixx>0.0430833</ixx>
          <ixy>0</ixy>
          <ixz>0.00625</ixz>
          <iyy>0.1285</iyy>
          <iyz>0</iyz>
          <izz>0.126208</izz>
        </inertia>
      </inertial>
      <collision name='link_chassis_fixed_joint_lump__collision_chassis_collision'>
        <pose>0 0 0 0 -0 0</pose>
        <geometry>
          <box>
            <size>0.5 0.3 0.07</size>
          </box>
        </geometry>
      </collision>
      <collision name='link_chassis_fixed_joint_lump__caster_front_collision_collision_1'>
        <pose>0.35 0 -0.05 0 -0 0</pose>
        <geometry>
          <sphere>
            <radius>0.05</radius>
          </sphere>
        </geometry>
      </collision>
      <collision name='link_chassis_fixed_joint_lump__sensor_laser_collision_2'>
        <pose>0.15 0 0.05 0 -0 0</pose>
        <geometry>
          <cylinder>
            <length>0.1</length>
            <radius>0.05</radius>
          </cylinder>
        </geometry>
        <surface>
          <contact>
            <ode/>
          </contact>
          <friction>
            <ode/>
          </friction>
        </surface>
      </collision>
      <visual name='link_chassis_visual'>
        <pose>0 0 0 0 -0 0</pose>
        <geometry>
          <box>
            <size>0.5 0.3 0.07</size>
          </box>
        </geometry>
        <material>
          <script>
            <name>Gazebo/Orange</name>
            <uri>file://media/materials/scripts/gazebo.material</uri>
          </script>
        </material>
      </visual>
      <visual name='link_chassis_fixed_joint_lump__caster_front_visual_visual_1'>
        <pose>0.2 0 -0.05 0 -0 0</pose>
        <geometry>
          <sphere>
            <radius>0.05</radius>
          </sphere>
        </geometry>
      </visual>
      <visual name='link_chassis_fixed_joint_lump__sensor_laser_visual_2'>
        <pose>0.15 0 0.05 0 -0 0</pose>
        <geometry>
          <cylinder>
            <length>0.1</length>
            <radius>0.05</radius>
          </cylinder>
        </geometry>
      </visual>
      <sensor name='head_hokuyo_sensor' type='ray'>
        <visualize>0</visualize>
        <update_rate>20</update_rate>
        <ray>
          <scan>
            <horizontal>
              <samples>720</samples>
              <resolution>1</resolution>
              <min_angle>-1.5708</min_angle>
              <max_angle>1.5708</max_angle>
            </horizontal>
          </scan>
          <range>
            <min>0.1</min>
            <max>10</max>
            <resolution>0.01</resolution>
          </range>
          <noise>
            <type>gaussian</type>
            <mean>0</mean>
            <stddev>0.01</stddev>
          </noise>
        </ray>
        <plugin name='gazebo_ros_head_hokuyo_controller' filename='libgazebo_ros_laser.so'>
          <topicName>/m2wr/laser/scan</topicName>
          <frameName>sensor_laser</frameName>
        </plugin>
        <pose>0.15 0 0.05 0 -0 0</pose>
      </sensor>
    </link>
    <joint name='joint_left_wheel' type='revolute'>
      <pose relative_to='link_chassis'>-0.05 -0.2 0 0 -0 0</pose>
      <parent>link_chassis</parent>
      <child>link_left_wheel</child>
      <axis>
        <xyz>0 1 0</xyz>
        <limit>
          <effort>10000</effort>
          <velocity>1000</velocity>
          <lower>-1e+16</lower>
          <upper>1e+16</upper>
        </limit>
        <dynamics>
          <spring_reference>0</spring_reference>
          <spring_stiffness>0</spring_stiffness>
        </dynamics>
      </axis>
    </joint>
    <link name='link_left_wheel'>
      <pose relative_to='joint_left_wheel'>0 0 0 0 -0 0</pose>
      <inertial>
        <pose>0 0 0 0 1.5707 1.5707</pose>
        <mass>0.4</mass>
        <inertia>
          <ixx>0.000526667</ixx>
          <ixy>0</ixy>
          <ixz>0</ixz>
          <iyy>0.000526667</iyy>
          <iyz>0</iyz>
          <izz>0.001</izz>
        </inertia>
      </inertial>
      <collision name='link_left_wheel_fixed_joint_lump__link_right_wheel_collision_collision'>
        <pose>0 0 0 -1.5707 1.5708 0</pose>
        <geometry>
          <cylinder>
            <length>0.04</length>
            <radius>0.1</radius>
          </cylinder>
        </geometry>
      </collision>
      <visual name='link_left_wheel_visual_visual'>
        <pose>0 0 0 -1.5707 1.5708 0</pose>
        <geometry>
          <cylinder>
            <length>0.04</length>
            <radius>0.1</radius>
          </cylinder>
        </geometry>
        <material>
          <script>
            <name>Gazebo/Blue</name>
            <uri>file://media/materials/scripts/gazebo.material</uri>
          </script>
        </material>
      </visual>
    </link>
    <joint name='joint_right_wheel' type='revolute'>
      <pose relative_to='link_chassis'>-0.05 0.2 0 0 -0 0</pose>
      <parent>link_chassis</parent>
      <child>link_right_wheel</child>
      <axis>
        <xyz>0 1 0</xyz>
        <limit>
          <effort>10000</effort>
          <velocity>1000</velocity>
          <lower>-1e+16</lower>
          <upper>1e+16</upper>
        </limit>
        <dynamics>
          <spring_reference>0</spring_reference>
          <spring_stiffness>0</spring_stiffness>
        </dynamics>
      </axis>
    </joint>
    <link name='link_right_wheel'>
      <pose relative_to='joint_right_wheel'>0 0 0 0 -0 0</pose>
      <inertial>
        <pose>0 0 0 0 1.5707 1.5707</pose>
        <mass>0.4</mass>
        <inertia>
          <ixx>0.000526667</ixx>
          <ixy>0</ixy>
          <ixz>0</ixz>
          <iyy>0.000526667</iyy>
          <iyz>0</iyz>
          <izz>0.001</izz>
        </inertia>
      </inertial>
      <collision name='link_right_wheel_collision_collision'>
        <pose>0 0 0 -1.5707 1.5708 0</pose>
        <geometry>
          <cylinder>
            <length>0.04</length>
            <radius>0.1</radius>
          </cylinder>
        </geometry>
        <surface>
          <contact>
            <ode/>
          </contact>
          <friction>
            <ode/>
          </friction>
        </surface>
      </collision>
      <visual name='link_right_wheel_visual_visual'>
        <pose>0 0 0 -1.5707 1.5708 0</pose>
        <geometry>
          <cylinder>
            <length>0.04</length>
            <radius>0.1</radius>
          </cylinder>
        </geometry>
        <material>
          <script>
            <name>Gazebo/Blue</name>
            <uri>file://media/materials/scripts/gazebo.material</uri>
          </script>
        </material>
      </visual>
    </link>
    <plugin name='differential_drive_controller' filename='libgazebo_ros_diff_drive.so'>
      <alwaysOn>1</alwaysOn>
      <updateRate>20</updateRate>
      <leftJoint>joint_left_wheel</leftJoint>
      <rightJoint>joint_right_wheel</rightJoint>
      <wheelSeparation>0.4</wheelSeparation>
      <wheelDiameter>0.2</wheelDiameter>
      <torque>0.1</torque>
      <commandTopic>cmd_vel</commandTopic>
      <odometryTopic>odom</odometryTopic>
      <odometryFrame>odom</odometryFrame>
      <robotBaseFrame>link_chassis</robotBaseFrame>
    </plugin>
    <frame name='joint_sensor_laser' attached_to='link_chassis'>
      <pose>0.15 0 0.05 0 -0 0</pose>
    </frame>
    <frame name='sensor_laser' attached_to='joint_sensor_laser'/>
  </model>
</sdf>
